<?xml version="1.0" encoding="utf-8"?>
<!-- These are atlas torso and limb models, for full Atlas robot model, please see
     xacro files containing fully assembed robots in ocs2_pros_gazebo2/robots/ -->
<robot name="pros_walker">
    <material name="black">
        <color rgba="0.0 0.0 0.0 1.0"/>
    </material>
    <material name="blue">
        <color rgba="0.0 0.0 0.8 1.0"/>
    </material>
    <material name="green">
        <color rgba="0.0 0.8 0.0 1.0"/>
    </material>
    <link name="l_foot">
        <inertial>
            <mass value="1.634" />
            <origin xyz="0.027 0 -0.067" rpy="0 -0 0" />
            <inertia ixx="0.002" ixy="0" ixz="0" iyy="0.007" iyz="0" izz="0.008" />
        </inertial>
        <visual>
            <origin xyz="0 0 0" rpy="0 -0 0" />
            <geometry>
                <mesh filename="package://ocs2_pros_gazebo2/meshes/l_foot.dae" scale="1 1 1" />
            </geometry>
        </visual>
        <!-- bottom -->
        <collision>
          <origin xyz="0.048 0 -0.056119" rpy="0 0 0"/>
          <geometry>
            <box size="0.26 0.124887 0.05"/>
          </geometry>
        </collision>
        <!-- ankle FIXME: adding this collision body destabilizes robot, shouldn't
        <collision>
          <origin xyz="0.0 0 -0.0528735" rpy="0 0 0"/>
          <geometry>
            <cylinder radius="0.0373" length="0.037827"/>
          </geometry>
        </collision>
        -->
    </link>
    <link name="l_lglut">
        <inertial>
            <mass value="0.69" />
            <origin xyz="0.0133341 0.0170484 -0.0312052" rpy="0 -0 0" />
            <inertia ixx="0.000691326" ixy="-2.24344e-05" ixz="2.50508e-06" iyy="0.00126856" iyz="0.000137862" izz="0.00106487" />
        </inertial>
        <visual>
            <origin xyz="0 0 0" rpy="0 -0 0" />
            <geometry>
                <mesh filename="package://ocs2_pros_gazebo2/meshes/l_lglut.dae" scale="1 1 1" />
            </geometry>
        </visual>
        <collision>
          <origin rpy="1.5707963267949 0 0" xyz="0.049968 0.022488 -0.0501165"/>
          <geometry>
            <cylinder radius="0.02009687" length="0.060306"/>
          </geometry>
        </collision>
        <collision>
          <origin rpy="0 1.5707963267949 0" xyz="0 0 0"/>
          <geometry>
            <cylinder radius="0.02" length="0.12"/>
          </geometry>
        </collision>
    </link>
    <link name="l_lleg">
        <inertial>
            <mass value="4.367" />
            <origin xyz="0.001 0 -0.187" rpy="0 -0 0" />
            <inertia ixx="0.077" ixy="0" ixz="-0.003" iyy="0.076" iyz="0" izz="0.01" />
        </inertial>
        <visual>
            <origin xyz="0 0 0" rpy="0 -0 0" />
            <geometry>
                <mesh filename="package://ocs2_pros_gazebo2/meshes/l_lleg.dae" scale="1.0 1.0 1.0" />
            </geometry>
        </visual>
        <collision>
          <origin rpy="0 0.10 0" xyz="0.02 0.00295 -0.18"/>
          <geometry>
            <cylinder radius="0.07" length="0.40"/>
          </geometry>
        </collision>
    </link>

    <link name="l_talus">
        <inertial>
            <mass value="0.1" />
            <origin xyz="0 0 0" rpy="0 -0 0" />
            <inertia ixx="1.01674e-05" ixy="0" ixz="0" iyy="8.42775e-06" iyz="0" izz="1.30101e-05" />
        </inertial>
        <visual>
            <origin xyz="0 0 0" rpy="0 -0 0" />
            <geometry>
                <mesh filename="package://ocs2_pros_gazebo2/meshes/l_talus.dae" scale="1 1 1" />
            </geometry>
        </visual>
        <collision>
          <origin rpy="0 1.5707963267949 0" xyz="0 0 0"/>
          <geometry>
            <cylinder radius="0.010181" length="0.029542"/>
          </geometry>
        </collision>
        <collision>
          <origin rpy="1.5707963267949 0 0" xyz="0 0 0"/>
          <geometry>
            <cylinder radius="0.010348" length="0.010059"/>
          </geometry>
        </collision>
    </link>
    <link name="l_uglut">
        <inertial>
            <mass value="0.5166" />
            <origin xyz="0.00529262 -0.00344732 0.00313046" rpy="0 -0 0" />
            <inertia ixx="0.00074276" ixy="-3.79607e-08" ixz="-2.79549e-05" iyy="0.000688179" iyz="-3.2735e-08" izz="0.00041242" />
        </inertial>
        <visual>
            <origin xyz="0 0 0" rpy="0 -0 0" />
            <geometry>
                <mesh filename="package://ocs2_pros_gazebo2/meshes/l_uglut.dae" scale="1 1 1" />
            </geometry>
        </visual>
        <collision>
          <origin rpy="0 1.5707963267949 0" xyz="0 0 0"/>
          <geometry>
            <cylinder radius="0.019096" length="0.078396"/>
          </geometry>
        </collision>
        <collision>
          <origin rpy="0 0 0" xyz="0 0 0"/>
          <geometry>
            <cylinder radius="0.019841" length="0.080842"/>
          </geometry>
        </collision>
    </link>
    <link name="l_uleg">
        <inertial>
            <mass value="7.34" />
            <origin xyz="0 0 -0.21" rpy="0 -0 0" />
            <inertia ixx="0.09" ixy="0" ixz="0" iyy="0.09" iyz="0" izz="0.02" />
        </inertial>
        <visual>
            <origin xyz="0 0 0" rpy="0 -0 0" />
            <geometry>
                <mesh filename="package://ocs2_pros_gazebo2/meshes/l_uleg.dae" scale="1.0 1.0 1.0" />
            </geometry>
        </visual>
        <collision>
          <origin rpy="0 0 0" xyz="-0.0179 0.02085 -0.13"/>
          <geometry>
            <cylinder radius="0.1" length="0.10"/>
          </geometry>
        </collision>
        <collision>
          <origin rpy="0 -0.3 0" xyz="-0.03 0.01 -0.23"/>
          <geometry>
            <cylinder radius="0.07" length="0.15"/>
          </geometry>
        </collision>
        <collision>
          <origin rpy="0 0.3 0" xyz="-0.005 0.01 -0.23"/>
          <geometry>
            <cylinder radius="0.07" length="0.15"/>
          </geometry>
        </collision>
        <collision>
          <origin rpy="-0.25 0 0" xyz="-0.02 0.03 -0.23"/>
          <geometry>
            <cylinder radius="0.07" length="0.15"/>
          </geometry>
        </collision>
    </link>
    <!-- <link name="ltorso">
        <inertial>
            <mass value="1.92" />
            <origin xyz="-0.0112984 -3.15366e-06 0.0746835" rpy="0 -0 0" />
            <inertia ixx="0.0039092" ixy="-5.04491e-08" ixz="-0.000342157" iyy="0.00341694" iyz="4.87119e-07" izz="0.00174492" />
        </inertial>
        <visual>
            <origin xyz="0 0 0" rpy="0 -0 0" />
            <geometry>
                <mesh filename="package://ocs2_pros_gazebo2/meshes/ltorso.dae" scale="1 1 1" />
            </geometry>
        </visual> -->
        <!-- this part is completely internal -->
        <!-- <collision>
          <origin rpy="0 0 0" xyz="0 0 0.039762"/>
          <geometry>
            <cylinder radius="0.025918" length="0.076922"/>
          </geometry>
        </collision>
        <collision>
          <origin rpy="1.5707963267949 0 0" xyz="0 0.0250065 0.09025"/>
          <geometry>
            <cylinder radius="0.014828" length="0.020367"/>
          </geometry>
        </collision>
        <collision>
          <origin rpy="1.5707963267949 0 0" xyz="0 -0.0248895 0.09025"/>
          <geometry>
            <cylinder radius="0.014828" length="0.020169"/>
          </geometry>
        </collision>
       
    </link> -->
    <!-- <link name="mtorso">
        <inertial>
            <mass value="0.55" />
            <origin xyz="-0.00816266 -0.0131245 0.0305974" rpy="0 -0 0" />
            <inertia ixx="0.000454181" ixy="-6.10764e-05" ixz="3.94009e-05" iyy="0.000483282" iyz="5.27463e-05" izz="0.000444215" />
        </inertial>
        <visual>
            <origin xyz="0 0 0" rpy="0 -0 0" />
            <geometry>
                <mesh filename="package://ocs2_pros_gazebo2/meshes/mtorso.dae" scale="1 1 1" />
            </geometry>
        </visual>
        <collision>
          <origin rpy="1.5707963267949 0 0" xyz="0 0 0"/>
          <geometry>
            <cylinder radius="0.017" length="0.03"/>
          </geometry>
        </collision>
        <collision>
          <origin rpy="0 1.5707963267949 0" xyz="0.0285 0 0.05"/>
          <geometry>
            <cylinder radius="0.015" length="0.02"/>
          </geometry>
        </collision>
        <collision>
          <origin rpy="0 1.5707963267949 0" xyz="-0.0285 0 0.05"/>
          <geometry>
            <cylinder radius="0.015" length="0.02"/>
          </geometry>
        </collision>
    </link> -->
    <link name="base">
        <visual>
            <origin xyz="0 0 0" rpy="0 -0 0" />
            <geometry>
                <mesh filename="package://ocs2_pros_gazebo2/meshes/pelvis.dae" scale="1.0 1.0 1.0" />
            </geometry>
        </visual>
        <collision>
          <origin rpy="1.5707963267949 0 0" xyz="0.046 0.0 -0.02"/>
          <geometry>
            <cylinder radius="0.11" length="0.06"/>
          </geometry>
        </collision>
        <collision>
          <origin rpy="1.5707963267949 0 0" xyz="-0.03 0.0 -0.02"/>
          <geometry>
            <cylinder radius="0.11" length="0.06"/>
          </geometry>
        </collision>
        <collision>
          <origin rpy="0 0 0" xyz="0.01 0.042 0.09"/>
          <geometry>
            <cylinder radius="0.16" length="0.05"/>
          </geometry>
        </collision>
        <collision>
          <origin rpy="0 0 0" xyz="0.01 -0.042 0.09"/>
          <geometry>
            <cylinder radius="0.16" length="0.05"/>
          </geometry>
        </collision>
        <collision>
          <origin rpy="0 0 0" xyz="-0.1 0 -0.05"/>
          <geometry>
            <box size="0.1 0.15 0.2"/>
          </geometry>
        </collision>
    </link>
    <joint name="base_to_base_inertia" type="fixed">
        <parent link="base"/>
        <child link="base_inertia"/>
        <origin rpy="0 0 0" xyz="0 0 0"/>
    </joint>
    <link name="base_inertia">
      <inertial>
            <mass value="14.2529" />
            <origin xyz="0.0111 0 0.0271" rpy="0 -0 0" />
            <inertia ixx="0.1244" ixy="0.0008" ixz="-0.0007"
                     iyy="0.0958" iyz="-0.0005"
                     izz="0.1167" />
      </inertial>
    </link>
    
    <link name="r_foot">
        <inertial>
            <mass value="1.634" />
            <origin xyz="0.027 0 -0.067" rpy="0 -0 0" />
            <inertia ixx="0.002" ixy="0" ixz="0" iyy="0.007" iyz="0" izz="0.008" />
        </inertial>
        <visual>
            <origin xyz="0 0 0" rpy="0 -0 0" />
            <geometry>
                <mesh filename="package://ocs2_pros_gazebo2/meshes/r_foot.dae" scale="1 1 1" />
            </geometry>
        </visual>
        <!-- bottom -->
        <collision>
          <origin xyz="0.048 0 -0.056119" rpy="0 0 0"/>
          <geometry>
            <box size="0.26 0.124887 0.05"/>
          </geometry>
        </collision>
        <!-- ankle FIXME: adding this collision body destabilizes robot, shouldn't
        <collision>
          <origin xyz="0.0 0 -0.0528735" rpy="0 0 0"/>
          <geometry>
            <cylinder radius="0.0373" length="0.037827"/>
          </geometry>
        </collision>
        -->
    </link>


    <link name="r_lglut">
        <inertial>
            <mass value="0.69" />
            <origin xyz="0.0133341 -0.0170484 -0.0312052" rpy="0 -0 0" />
            <inertia ixx="0.000691326" ixy="2.24344e-05" ixz="2.50508e-06" iyy="0.00126856" iyz="-0.000137862" izz="0.00106487" />
        </inertial>
        <visual>
            <origin xyz="0 0 0" rpy="0 -0 0" />
            <geometry>
                <mesh filename="package://ocs2_pros_gazebo2/meshes/r_lglut.dae" scale="1.0 1.0 1.0" />
            </geometry>
        </visual>
        <collision>
          <origin rpy="1.5707963267949 0 0" xyz="0.049968 -0.022488 -0.0501165"/>
          <geometry>
            <cylinder radius="0.02009687" length="0.060306"/>
          </geometry>
        </collision>
        <collision>
          <origin rpy="0 1.5707963267949 0" xyz="0 0 0"/>
          <geometry>
            <cylinder radius="0.02" length="0.12"/>
          </geometry>
        </collision>
    </link>
    <link name="r_lleg">
        <inertial>
            <mass value="4.367" />
            <origin xyz="0.001 0 -0.187" rpy="0 -0 0" />
            <inertia ixx="0.077" ixy="-0" ixz="-0.003" iyy="0.076" iyz="-0" izz="0.01" />
        </inertial>
        <visual>
            <origin xyz="0 0 0" rpy="0 -0 0" />
            <geometry>
                <mesh filename="package://ocs2_pros_gazebo2/meshes/r_lleg.dae" scale="1.0 1.0 1.0" />
            </geometry>
        </visual>
        <collision>
          <origin rpy="0 0.10 0" xyz="0.02 -0.00295 -0.18"/>
          <geometry>
            <cylinder radius="0.07" length="0.40"/>
          </geometry>
        </collision>
    </link>
    <link name="r_talus">
        <inertial>
            <mass value="0.1" />
            <origin xyz="0 0 0" rpy="0 -0 0" />
            <inertia ixx="1.01674e-05" ixy="0" ixz="0" iyy="8.42775e-06" iyz="0" izz="1.30101e-05" />
        </inertial>
        <visual>
            <origin xyz="0 0 0" rpy="0 -0 0" />
            <geometry>
                <mesh filename="package://ocs2_pros_gazebo2/meshes/r_talus.dae" scale="1 1 1" />
            </geometry>
        </visual>
        <collision>
          <origin rpy="0 1.5707963267949 0" xyz="0 0 0"/>
          <geometry>
            <cylinder radius="0.010181" length="0.029542"/>
          </geometry>
        </collision>
        <collision>
          <origin rpy="1.5707963267949 0 0" xyz="0 0 0"/>
          <geometry>
            <cylinder radius="0.010348" length="0.010059"/>
          </geometry>
        </collision>
    </link>
    <link name="r_uglut">
        <inertial>
            <mass value="0.5166" />
            <origin xyz="0.00529262 0.00344732 0.00313046" rpy="0 -0 0" />
            <inertia ixx="0.00074276" ixy="3.79607e-08" ixz="-2.79549e-05" iyy="0.000688179" iyz="3.2735e-08" izz="0.00041242" />
        </inertial>
        <visual>
            <origin xyz="0 0 0" rpy="0 -0 0" />
            <geometry>
                <mesh filename="package://ocs2_pros_gazebo2/meshes/r_uglut.dae" scale="1.0 1.0 1.0" />
            </geometry>
        </visual>
        <collision>
          <origin rpy="0 1.5707963267949 0" xyz="0 0 0"/>
          <geometry>
            <cylinder radius="0.019096" length="0.078396"/>
          </geometry>
        </collision>
        <collision>
          <origin rpy="0 0 0" xyz="0 0 0"/>
          <geometry>
            <cylinder radius="0.019841" length="0.080842"/>
          </geometry>
        </collision>
    </link>
    <link name="r_uleg">
        <inertial>
            <mass value="7.34" />
            <origin xyz="0 0 -0.21" rpy="0 -0 0" />
            <inertia ixx="0.09" ixy="0" ixz="0" iyy="0.09" iyz="0" izz="0.02" />
        </inertial>
        <visual>
            <origin xyz="0 0 0" rpy="0 -0 0" />
            <geometry>
                <mesh filename="package://ocs2_pros_gazebo2/meshes/r_uleg.dae" scale="1.0 1.0 1.0" />
            </geometry>
        </visual>
        <collision>
          <origin rpy="0 0 0" xyz="-0.0179 -0.02085 -0.13"/>
          <geometry>
            <cylinder radius="0.1" length="0.10"/>
          </geometry>
        </collision>
        <collision>
          <origin rpy="0 -0.3 0" xyz="-0.03 -0.01 -0.23"/>
          <geometry>
            <cylinder radius="0.07" length="0.15"/>
          </geometry>
        </collision>
        <collision>
          <origin rpy="0 0.3 0" xyz="-0.005 -0.01 -0.23"/>
          <geometry>
            <cylinder radius="0.07" length="0.15"/>
          </geometry>
        </collision>
        <collision>
          <origin rpy="0.25 0 0" xyz="-0.02 -0.03 -0.23"/>
          <geometry>
            <cylinder radius="0.07" length="0.15"/>
          </geometry>
        </collision>
    </link>
    <!-- <link name="utorso">
        <inertial>
            <mass value="18.484" />
            <origin xyz="0.02 -0.001 0.211" rpy="0 -0 0" />
            <inertia ixx="0.395" ixy="0" ixz="0.083" iyy="1.089" iyz="-0.003" izz="0.327" />
            <inertia ixx="0.395" ixy="0" ixz="0.083" iyy="1.089" iyz="-0.003" izz="0.827" />
        </inertial>
        <visual>
            <origin xyz="0 0 0" rpy="0 -0 0" />
            <geometry>
                <mesh filename="package://ocs2_pros_gazebo2/meshes/utorso.dae" scale="1 1 1" />
            </geometry>
        </visual>
        <collision>
          <origin rpy="0 -0 0" xyz="0.0446 0 0.1869"/>
          <geometry>
            <box size="0.3188 0.24 0.3162"/>
          </geometry>
        </collision>
        <collision>
          <origin rpy="-0.5236 0 0" xyz="0.024 0.16 0.18"/>
          <geometry>
            <cylinder radius="0.0363" length="0.22375"/>
          </geometry>
        </collision>
        <collision>
          <origin rpy="0.5236 0 0" xyz="0.024 -0.16 0.18"/>
          <geometry>
            <cylinder radius="0.0363" length="0.22375"/>
          </geometry>
        </collision>
    </link> -->
    <!-- <joint name="back_lbz" type="revolute">
        <origin xyz="-0.0125 0 0" rpy="0 -0 0" />
        <axis xyz="0 0 1" />
        <parent link="base_inertia" />
        <child link="ltorso" />
        <dynamics damping="10" friction="0" />
        <limit effort="124.016" velocity="12" lower="-0.610865" upper="0.610865" />
        <safety_controller k_position="100" k_velocity="100" soft_lower_limit="-10.6109" soft_upper_limit="10.6109" />
    </joint> -->
    <!-- <joint name="back_mby" type="revolute">
        <origin xyz="0 0 0.09" rpy="0 -0 0" />
        <axis xyz="0 1 0" />
        <parent link="ltorso" />
        <child link="mtorso" />
        <dynamics damping="10" friction="0" />
        <limit effort="206.843" velocity="12" lower="-1.2" upper="1.28" />
        <safety_controller k_position="100" k_velocity="100" soft_lower_limit="-11.2" soft_upper_limit="11.28" />
    </joint> -->
    <!-- <joint name="back_ubx" type="revolute">
        <origin xyz="0 0 0.05" rpy="0 -0 0" />
        <axis xyz="1 0 0" />
        <parent link="mtorso" />
        <child link="utorso" />
        <dynamics damping="10" friction="0" />
        <limit effort="94.91" velocity="12" lower="-0.790809" upper="0.790809" />
        <safety_controller k_position="100" k_velocity="100" soft_lower_limit="-10.7908" soft_upper_limit="10.7908" />
    </joint> -->
    <joint name="l_leg_kny" type="revolute">
        <origin xyz="-0.05 0 -0.374" rpy="0 -0 0" />
        <axis xyz="0 1 0" />
        <parent link="l_uleg" />
        <child link="l_lleg" />
        <dynamics damping="1.0" friction="0" />
        <limit effort="400" velocity="12" lower="0" upper="2.45" />
        <safety_controller k_position="100" k_velocity="100" soft_lower_limit="-10" soft_upper_limit="12.45" />
    </joint>
    <joint name="l_leg_lax" type="revolute">
        <origin xyz="0 0 0" rpy="0 -0 0" />
        <axis xyz="1 0 0" />
        <parent link="l_talus" />
        <child link="l_foot" />
        <dynamics damping="1.0" friction="0" />
        <limit effort="90" velocity="12" lower="-0.436" upper="0.436" />
        <safety_controller k_position="100" k_velocity="100" soft_lower_limit="-10.436" soft_upper_limit="10.436" />
    </joint>
    <joint name="l_leg_lhy" type="revolute">
        <origin xyz="0.05 0 -0.05" rpy="0 -0 0" />
        <axis xyz="0 1 0" />
        <parent link="l_lglut" />
        <child link="l_uleg" />
        <dynamics damping="1.0" friction="0" />
        <limit effort="260" velocity="12" lower="-1.75" upper="0.524" />
        <safety_controller k_position="100" k_velocity="100" soft_lower_limit="-11.75" soft_upper_limit="10.524" />
    </joint>
    <joint name="l_leg_mhx" type="revolute">
        <origin xyz="0 0 0" rpy="0 -0 0" />
        <axis xyz="1 0 0" />
        <parent link="l_uglut" />
        <child link="l_lglut" />
        <dynamics damping="1.0" friction="0" />
        <limit effort="180" velocity="12" lower="-0.47" upper="0.495" />
        <safety_controller k_position="100" k_velocity="100" soft_lower_limit="-10.47" soft_upper_limit="10.495" />
    </joint>
    <joint name="l_leg_uay" type="revolute">
        <origin xyz="0 0 -0.422" rpy="0 -0 0" />
        <axis xyz="0 1 0" />
        <parent link="l_lleg" />
        <child link="l_talus" />
        <dynamics damping="1.0" friction="0" />
        <limit effort="220" velocity="12" lower="-0.9" upper="0.698" />
        <safety_controller k_position="100" k_velocity="100" soft_lower_limit="-10.698" soft_upper_limit="10.698" />
    </joint>
    <joint name="l_leg_uhz" type="revolute">
        <origin xyz="0 0.089 0" rpy="0 -0 0" />
        
        <parent link="base" />
        <child link="l_uglut" />
        <dynamics damping="1.0" friction="0" />
        <axis xyz="0 0 1" />
        <limit effort="110" velocity="12" lower="-0.32" upper="1.14" />
        <safety_controller k_position="100" k_velocity="100" soft_lower_limit="-10.32" soft_upper_limit="11.14" />
    </joint>
    <!-- <joint name="neck_ay" type="revolute">
        <origin xyz="0.21672 0 0.53796" rpy="0 -0 0" />
        <axis xyz="0 1 0" />
        <parent link="utorso" />
        <child link="head" />
        <dynamics damping="1.0" friction="0" />
        <limit effort="5" lower="-0.610865238" upper="1.13446401" velocity="12"/>
        <safety_controller k_position="100" k_velocity="100" soft_lower_limit="-10.610865238" soft_upper_limit="11.13446401"/>
    </joint> -->

    <joint name="r_leg_kny" type="revolute">
        <origin xyz="-0.05 0 -0.374" rpy="0 -0 0" />
        <axis xyz="0 1 0" />
        <parent link="r_uleg" />
        <child link="r_lleg" />
        <dynamics damping="1.0" friction="0" />
        <limit effort="400" velocity="12" lower="0" upper="2.45" />
        <safety_controller k_position="100" k_velocity="100" soft_lower_limit="-10" soft_upper_limit="12.45" />
    </joint>
    <joint name="r_leg_lax" type="revolute">
        <origin xyz="0 0 0" rpy="0 -0 0" />
        <axis xyz="1 0 0" />
        <parent link="r_talus" />
        <child link="r_foot" />
        <dynamics damping="1.0" friction="0" />
        <limit effort="90" velocity="12" lower="-0.436" upper="0.436" />
        <safety_controller k_position="100" k_velocity="100" soft_lower_limit="-10.436" soft_upper_limit="10.436" />
    </joint>
    <joint name="r_leg_lhy" type="revolute">
        <origin xyz="0.05 0 -0.05" rpy="0 -0 0" />
        <axis xyz="0 1 0" />
        <parent link="r_lglut" />
        <child link="r_uleg" />
        <dynamics damping="1.0" friction="0" />
        <limit effort="260" velocity="12" lower="-1.745" upper="0.524" />
        <safety_controller k_position="100" k_velocity="100" soft_lower_limit="-11.745" soft_upper_limit="10.524" />
    </joint>
    <joint name="r_leg_mhx" type="revolute">
        <origin xyz="0 0 0" rpy="0 -0 0" />
        <axis xyz="1 0 0" />
        <parent link="r_uglut" />
        <child link="r_lglut" />
        <dynamics damping="1.0" friction="0" />
        <limit effort="180" velocity="12" lower="-0.495" upper="0.47" />
        <safety_controller k_position="100" k_velocity="100" soft_lower_limit="-10.495" soft_upper_limit="10.47" />
    </joint>
    <joint name="r_leg_uay" type="revolute">
        <origin xyz="0 0 -0.422" rpy="0 -0 0" />
        <axis xyz="0 1 0" />
        <parent link="r_lleg" />
        <child link="r_talus" />
        <dynamics damping="1.0" friction="0" />
        <limit effort="220" velocity="12" lower="-0.9" upper="0.698" />
        <safety_controller k_position="100" k_velocity="100" soft_lower_limit="-10.698" soft_upper_limit="10.698" />
    </joint>
    <joint name="r_leg_uhz" type="revolute">
        <origin xyz="0 -0.089 0" rpy="0 -0 0" />
        <parent link="base" />
        <child link="r_uglut" />
        <dynamics damping="1.0" friction="0" /> 
        <axis xyz="0 0 1" />
        <limit effort="110" velocity="12" lower="-1.14" upper="0.32" />
        <safety_controller k_position="100" k_velocity="100" soft_lower_limit="-11.14" soft_upper_limit="10.32" />
    </joint>

    <joint name="fp0_fixed_r_foot" type="fixed">
        <parent link="r_foot"/>
        <child link="fp0_r"/>
        <origin rpy="0 0 0" xyz="0.05 0 -0.08"/>
    </joint>
    <!-- Foot link -->
    <link name="fp0_r">
        <visual>
           <origin rpy="0 0 0" xyz="0 0 0"/>
            <geometry>
                <sphere radius="0.01"/>
            </geometry>
        </visual>
        <!-- Adapter collision -->
        <collision>
            <origin rpy="0 0 0" xyz="0 0 0"/>
            <geometry>
                <sphere radius="0.01"/>
            </geometry>
        </collision>
        <!-- Foot collision -->
        <collision>
            <origin xyz="0 0 0"/>
            <geometry>
                <sphere radius="0.01"/>
            </geometry>
        </collision>
        <inertial>
            <origin rpy="0 0 0" xyz="0.0 0.0 0.0"/>
            <mass value="0.1"/>
            <inertia ixx="4e-06" ixy="0" ixz="0" 
                    iyy="4e-06" iyz="0" izz="4e-06"/>
        </inertial>
    </link>
    <joint name="fp0_fixed_l_foot" type="fixed">
        <parent link="l_foot"/>
        <child link="fp0_l"/>
        <origin rpy="0 0 0" xyz="0.05 0 -0.08"/>
    </joint>
    <!-- Foot link -->
    <link name="fp0_l">
        <visual>
           <origin rpy="0 0 0" xyz="0 0 0"/>
            <geometry>
                <sphere radius="0.01"/>
            </geometry>
        </visual>
        <!-- Adapter collision -->
        <collision>
            <origin rpy="0 0 0" xyz="0 0 0"/>
            <geometry>
                <sphere radius="0.01"/>
            </geometry>
        </collision>
        <!-- Foot collision -->
        <collision>
            <origin xyz="0 0 0"/>
            <geometry>
                <sphere radius="0.01"/>
            </geometry>
        </collision>
        <inertial>
            <origin rpy="0 0 0" xyz="0.0 0.0 0.0"/>
            <mass value="0.1"/>
            <inertia ixx="4e-06" ixy="0" ixz="0" 
                    iyy="4e-06" iyz="0" izz="4e-06"/>
        </inertial>
    </link>
    <joint name="fp1_fixed_r_foot" type="fixed">
        <parent link="r_foot"/>
        <child link="fp1_r"/>
        <origin rpy="0 0 0" xyz="0.18 0.03 -0.08"/>
    </joint>
    <!-- Foot link -->
    <link name="fp1_r">
        <visual>
           <origin rpy="0 0 0" xyz="0 0 0"/>
            <geometry>
                <sphere radius="0.01"/>
            </geometry>
        </visual>
        <!-- Adapter collision -->
        <collision>
            <origin rpy="0 0 0" xyz="0 0 0"/>
            <geometry>
                <sphere radius="0.01"/>
            </geometry>
        </collision>
        <!-- Foot collision -->
        <collision>
            <origin xyz="0 0 0"/>
            <geometry>
                <sphere radius="0.01"/>
            </geometry>
        </collision>
        <inertial>
            <origin rpy="0 0 0" xyz="0.0 0.0 0.0"/>
            <mass value="0.1"/>
            <inertia ixx="4e-06" ixy="0" ixz="0" 
                    iyy="4e-06" iyz="0" izz="4e-06"/>
        </inertial>
    </link>

    <joint name="fp2_fixed_r_foot" type="fixed">
        <parent link="r_foot"/>
        <child link="fp2_r"/>
        <origin rpy="0 0 0" xyz="0.18 -0.03 -0.08"/>
    </joint>
    <!-- Foot link -->
    <link name="fp2_r">
        <visual>
           <origin rpy="0 0 0" xyz="0 0 0"/>
            <geometry>
                <sphere radius="0.01"/>
            </geometry>
        </visual>
        <!-- Adapter collision -->
        <collision>
            <origin rpy="0 0 0" xyz="0 0 0"/>
            <geometry>
                <sphere radius="0.01"/>
            </geometry>
        </collision>
        <!-- Foot collision -->
        <collision>
            <origin xyz="0 0 0"/>
            <geometry>
                <sphere radius="0.01"/>
            </geometry>
        </collision>
        <inertial>
            <origin rpy="0 0 0" xyz="0.0 0.0 0.0"/>
            <mass value="0.1"/>
            <inertia ixx="4e-06" ixy="0" ixz="0" 
                    iyy="4e-06" iyz="0" izz="4e-06"/>
        </inertial>
    </link>

    <joint name="fp3_fixed_r_foot" type="fixed">
        <parent link="r_foot"/>
        <child link="fp3_r"/>
        <origin rpy="0 0 0" xyz="-0.08 0.035 -0.08"/>
    </joint>
    <!-- Foot link -->
    <link name="fp3_r">
        <visual>
           <origin rpy="0 0 0" xyz="0 0 0"/>
            <geometry>
                <sphere radius="0.01"/>
            </geometry>
        </visual>
        <!-- Adapter collision -->
        <collision>
            <origin rpy="0 0 0" xyz="0 0 0"/>
            <geometry>
                <sphere radius="0.01"/>
            </geometry>
        </collision>
        <!-- Foot collision -->
        <collision>
            <origin xyz="0 0 0"/>
            <geometry>
                <sphere radius="0.01"/>
            </geometry>
        </collision>
        <inertial>
            <origin rpy="0 0 0" xyz="0.0 0.0 0.0"/>
            <mass value="0.1"/>
            <inertia ixx="4e-06" ixy="0" ixz="0" 
                    iyy="4e-06" iyz="0" izz="4e-06"/>
        </inertial>
    </link>
    <joint name="fp4_fixed_r_foot" type="fixed">
        <parent link="r_foot"/>
        <child link="fp4_r"/>
        <origin rpy="0 0 0" xyz="-0.08 -0.035 -0.08"/>
    </joint>
    <!-- Foot link -->
    <link name="fp4_r">
        <visual>
           <origin rpy="0 0 0" xyz="0 0 0"/>
            <geometry>
                <sphere radius="0.01"/>
            </geometry>
        </visual>
        <!-- Adapter collision -->
        <collision>
            <origin rpy="0 0 0" xyz="0 0 0"/>
            <geometry>
                <sphere radius="0.01"/>
            </geometry>
        </collision>
        <!-- Foot collision -->
        <collision>
            <origin xyz="0 0 0"/>
            <geometry>
                <sphere radius="0.01"/>
            </geometry>
        </collision>
        <inertial>
            <origin rpy="0 0 0" xyz="0.0 0.0 0.0"/>
            <mass value="0.1"/>
            <inertia ixx="4e-06" ixy="0" ixz="0" 
                    iyy="4e-06" iyz="0" izz="4e-06"/>
        </inertial>
    </link>

    <joint name="fp1_fixed_l_foot" type="fixed">
        <parent link="l_foot"/>
        <child link="fp1_l"/>
        <origin rpy="0 0 0" xyz="0.18 0.03 -0.08"/>
    </joint>
    <!-- Foot link -->
    <link name="fp1_l">
        <visual>
           <origin rpy="0 0 0" xyz="0 0 0"/>
            <geometry>
                <sphere radius="0.01"/>
            </geometry>
        </visual>
        <!-- Adapter collision -->
        <collision>
            <origin rpy="0 0 0" xyz="0 0 0"/>
            <geometry>
                <sphere radius="0.01"/>
            </geometry>
        </collision>
        <!-- Foot collision -->
        <collision>
            <origin xyz="0 0 0"/>
            <geometry>
                <sphere radius="0.01"/>
            </geometry>
        </collision>
        <inertial>
            <origin rpy="0 0 0" xyz="0.0 0.0 0.0"/>
            <mass value="0.1"/>
            <inertia ixx="4e-06" ixy="0" ixz="0" 
                    iyy="4e-06" iyz="0" izz="4e-06"/>
        </inertial>
    </link>

    <joint name="fp2_fixed_l_foot" type="fixed">
        <parent link="l_foot"/>
        <child link="fp2_l"/>
        <origin rpy="0 0 0" xyz="0.18 -0.03 -0.08"/>
    </joint>
    <!-- Foot link -->
    <link name="fp2_l">
        <visual>
           <origin rpy="0 0 0" xyz="0 0 0"/>
            <geometry>
                <sphere radius="0.01"/>
            </geometry>
        </visual>
        <!-- Adapter collision -->
        <collision>
            <origin rpy="0 0 0" xyz="0 0 0"/>
            <geometry>
                <sphere radius="0.01"/>
            </geometry>
        </collision>
        <!-- Foot collision -->
        <collision>
            <origin xyz="0 0 0"/>
            <geometry>
                <sphere radius="0.01"/>
            </geometry>
        </collision>
        <inertial>
            <origin rpy="0 0 0" xyz="0.0 0.0 0.0"/>
            <mass value="0.1"/>
            <inertia ixx="4e-06" ixy="0" ixz="0" 
                    iyy="4e-06" iyz="0" izz="4e-06"/>
        </inertial>
    </link>

    <joint name="fp3_fixed_l_foot" type="fixed">
        <parent link="l_foot"/>
        <child link="fp3_l"/>
        <origin rpy="0 0 0" xyz="-0.08 0.035 -0.08"/>
    </joint>
    <!-- Foot link -->
    <link name="fp3_l">
        <visual>
           <origin rpy="0 0 0" xyz="0 0 0"/>
            <geometry>
                <sphere radius="0.01"/>
            </geometry>
        </visual>
        <!-- Adapter collision -->
        <collision>
            <origin rpy="0 0 0" xyz="0 0 0"/>
            <geometry>
                <sphere radius="0.01"/>
            </geometry>
        </collision>
        <!-- Foot collision -->
        <collision>
            <origin xyz="0 0 0"/>
            <geometry>
                <sphere radius="0.01"/>
            </geometry>
        </collision>
        <inertial>
            <origin rpy="0 0 0" xyz="0.0 0.0 0.0"/>
            <mass value="0.1"/>
            <inertia ixx="4e-06" ixy="0" ixz="0" 
                    iyy="4e-06" iyz="0" izz="4e-06"/>
        </inertial>
    </link>
    <joint name="fp4_fixed_l_foot" type="fixed">
        <parent link="l_foot"/>
        <child link="fp4_l"/>
        <origin rpy="0 0 0" xyz="-0.08 -0.035 -0.08"/>
    </joint>
    <!-- Foot link -->
    <link name="fp4_l">
        <visual>
           <origin rpy="0 0 0" xyz="0 0 0"/>
            <geometry>
                <sphere radius="0.01"/>
            </geometry>
        </visual>
        <!-- Adapter collision -->
        <collision>
            <origin rpy="0 0 0" xyz="0 0 0"/>
            <geometry>
                <sphere radius="0.01"/>
            </geometry>
        </collision>
        <!-- Foot collision -->
        <collision>
            <origin xyz="0 0 0"/>
            <geometry>
                <sphere radius="0.01"/>
            </geometry>
        </collision>
        <inertial>
            <origin rpy="0 0 0" xyz="0.0 0.0 0.0"/>
            <mass value="0.1"/>
            <inertia ixx="4e-06" ixy="0" ixz="0" 
                    iyy="4e-06" iyz="0" izz="4e-06"/>
        </inertial>
    </link>

     <!-- <joint name="find_base_fixed" type="fixed">
        <parent link="base"/>
        <child link="find_base"/>
        <origin rpy="0 0 0" xyz="0 0 -0.925"/>
    </joint>
    <link name="find_base">
        <visual>
           <origin rpy="0 0 0" xyz="0 0 0"/>
            <geometry>
                <sphere radius="0.01"/>
            </geometry>
        </visual>
        <collision>
            <origin rpy="0 0 0" xyz="0 0 0"/>
            <geometry>
                <sphere radius="0.01"/>
            </geometry>
        </collision>
        <collision>
            <origin xyz="0 0 0"/>
            <geometry>
                <sphere radius="0.01"/>
            </geometry>
        </collision>
        <inertial>
            <origin rpy="0 0 0" xyz="0.0 0.0 0.0"/>
            <mass value="0.1"/>
            <inertia ixx="4e-06" ixy="0" ixz="0" 
                    iyy="4e-06" iyz="0" izz="4e-06"/>
        </inertial>
    </link> -->






</robot>